<?xml version="1.0"?>
<robot xmlns:xacro="http://www.ros.org/wiki/xacro" name="differential_drive_robot">

  <xacro:macro name="blue_shape" params="name *shape">
    <link name="${name}">
        <visual>
            <geometry>
                <xacro:insert_block name="shape" />
            </geometry>
            <material name="blue"/>
        </visual>
        <collision>
            <geometry>
                <xacro:insert_block name="shape" />
            </geometry>
        </collision>
        <inertial>
          <mass value="10.0"/>
          <inertia ixx="1.0" ixy="0.0" ixz="0.0" iyy="1.0" iyz="0.0" izz="1.0"/>
        </inertial>
    </link>
  </xacro:macro>

  


  <xacro:property name="base_len" value="0.25" />
  <xacro:property name="base_rad" value="0.5" />
  <xacro:property name="wheel_len" value="0.05" />
  <xacro:property name="wheel_rad" value="0.2" />

  <xacro:blue_shape name="base_link">
      <cylinder radius="${base_rad}" length="${base_len}" />
  </xacro:blue_shape>


  <!-- Left Wheel -->
  <link name="left_wheel">
    <visual>
      <geometry>
        <cylinder length="${wheel_len}" radius="${wheel_rad}"/>
      </geometry>
      <material name="black">
        <color rgba="0 0 0 1"/>
      </material>
    </visual>
    <collision>
      <geometry>
        <cylinder length="${wheel_len}" radius="${wheel_rad}"/>
      </geometry>
    </collision>
    <inertial>
      <mass value="1.0"/>
      <inertia ixx="0.01" ixy="0.0" ixz="0.0" iyy="0.01" iyz="0.0" izz="0.01"/>
    </inertial>
  </link>

  <!-- Right Wheel -->
  <link name="right_wheel">
    <visual>
      <geometry>
        <cylinder length="${wheel_len}" radius="${wheel_rad}"/>
      </geometry>
      <material name="black">
        <color rgba="0 0 0 1"/>
      </material>
    </visual>
    <collision>
      <geometry>
        <cylinder length="${wheel_len}" radius="${wheel_rad}"/>
      </geometry>
    </collision>
    <inertial>
      <mass value="1.0"/>
      <inertia ixx="0.01" ixy="0.0" ixz="0.0" iyy="0.01" iyz="0.0" izz="0.01"/>
    </inertial>
  </link>

  <!-- Joints -->
  <joint name="left_wheel_joint" type="continuous">
    <parent link="base_link"/>
    <child link="left_wheel"/>
    <origin xyz="-0.3 0.4 -0.1" rpy="0 1.5708 1.5708"/>
    <axis xyz="0 0 1"/>
  </joint>

  <joint name="right_wheel_joint" type="continuous">
    <parent link="base_link"/>
    <child link="right_wheel"/>
    <origin xyz="-0.3 -0.4 -0.1" rpy="0 1.5708 1.5708"/>
    <axis xyz="0 0 1"/>
  </joint>

</robot>